{
  "debianbug": 768408,
  "description": "python-requests-Kerberos through 0.5 does not handle mutual authentication",
  "releases": {
    "bullseye": {
      "fixed_version": "0.5-2",
      "repositories": {
        "bullseye": "0.12.0-2"
      },
      "status": "resolved",
      "urgency": "not yet assigned"
    },
    "buster": {
      "fixed_version": "0.5-2",
      "repositories": {
        "buster": "0.11.0-2"
      },
      "status": "resolved",
      "urgency": "not yet assigned"
    },
    "sid": {
      "fixed_version": "0.5-2",
      "repositories": {
        "sid": "0.12.0-2"
      },
      "status": "resolved",
      "urgency": "not yet assigned"
    },
    "stretch": {
      "fixed_version": "0.5-2",
      "repositories": {
        "stretch": "0.7.0-3"
      },
      "status": "resolved",
      "urgency": "not yet assigned"
    }
  },
  "scope": "local"
}