{
  "debianbug": 599711,
  "description": "Race condition in ZEO/StorageServer.py in Zope Object Database (ZODB) before 3.10.0 allows remote attackers to cause a denial of service (daemon outage) by establishing and then immediately closing a TCP connection, leading to the accept function having an unexpected return value of None, an unexpected value of None for the address, or an ECONNABORTED, EAGAIN, or EWOULDBLOCK error, a related issue to CVE-2010-3492.",
  "releases": {
    "buster": {
      "fixed_version": "1:3.9.4-1.1",
      "repositories": {
        "buster": "1:3.10.7-1"
      },
      "status": "resolved",
      "urgency": "not yet assigned"
    },
    "stretch": {
      "fixed_version": "1:3.9.4-1.1",
      "repositories": {
        "stretch": "1:3.10.7-1"
      },
      "status": "resolved",
      "urgency": "not yet assigned"
    }
  },
  "scope": "local"
}