{
  "debianbug": 796195,
  "description": "The checkPassword function in python-kerberos does not authenticate the KDC it attempts to communicate with, which allows remote attackers to cause a denial of service (bad response), or have other unspecified impact by performing a man-in-the-middle attack.",
  "releases": {
    "bullseye": {
      "fixed_version": "1.1.5-1",
      "repositories": {
        "bullseye": "1.1.14-3.1"
      },
      "status": "resolved",
      "urgency": "not yet assigned"
    },
    "buster": {
      "fixed_version": "1.1.5-1",
      "repositories": {
        "buster": "1.1.14-2"
      },
      "status": "resolved",
      "urgency": "not yet assigned"
    },
    "sid": {
      "fixed_version": "1.1.5-1",
      "repositories": {
        "sid": "1.1.14-3.1"
      },
      "status": "resolved",
      "urgency": "not yet assigned"
    },
    "stretch": {
      "fixed_version": "1.1.5-1",
      "repositories": {
        "stretch": "1.1.5-2"
      },
      "status": "resolved",
      "urgency": "not yet assigned"
    }
  },
  "scope": "local"
}